<?xml version="1.0" encoding="UTF-8"?>
<testng-results skipped="1" failed="4" total="12" passed="7">
  <reporter-output>
  </reporter-output>
  <suite name="Suite B" duration-ms="45" started-at="2017-01-20T07:12:41Z" finished-at="2017-01-20T07:12:41Z">
    <groups>
    </groups>
    <test name="Test B1" duration-ms="1" started-at="2017-01-20T07:12:41Z" finished-at="2017-01-20T07:12:41Z">
      <class name="testSuiteB.TestB1">
        <test-method status="PASS" signature="testB1_1()[pri:0, instance:testSuiteB.TestB1@256216b3]" name="testB1_1" duration-ms="0" started-at="2017-01-20T00:12:41Z" finished-at="2017-01-20T00:12:41Z">
          <reporter-output>
          </reporter-output>
        </test-method> <!-- testB1_1 -->
        <test-method status="PASS" signature="testB1_2()[pri:0, instance:testSuiteB.TestB1@256216b3]" name="testB1_2" duration-ms="0" started-at="2017-01-20T00:12:41Z" finished-at="2017-01-20T00:12:41Z">
          <reporter-output>
          </reporter-output>
        </test-method> <!-- testB1_2 -->
        <test-method status="FAIL" signature="testB1_3()[pri:0, instance:testSuiteB.TestB1@256216b3]" name="testB1_3" duration-ms="0" started-at="2017-01-20T00:12:41Z" finished-at="2017-01-20T00:12:41Z">
          <exception class="java.lang.AssertionError">
            <message>
              <![CDATA[failed test case ]]>
            </message>
            <full-stacktrace>
              <![CDATA[java.lang.AssertionError: failed test case 
	at org.testng.Assert.fail(Assert.java:94)
	at testSuiteB.TestB1.testB1_3(TestB1.java:22)
	at sun.reflect.NativeMethodAccessorImpl.invoke0(Native Method)
	at sun.reflect.NativeMethodAccessorImpl.invoke(NativeMethodAccessorImpl.java:62)
	at sun.reflect.DelegatingMethodAccessorImpl.invoke(DelegatingMethodAccessorImpl.java:43)
	at java.lang.reflect.Method.invoke(Method.java:498)
	at org.testng.internal.MethodInvocationHelper.invokeMethod(MethodInvocationHelper.java:85)
	at org.testng.internal.Invoker.invokeMethod(Invoker.java:639)
	at org.testng.internal.Invoker.invokeTestMethod(Invoker.java:816)
	at org.testng.internal.Invoker.invokeTestMethods(Invoker.java:1124)
	at org.testng.internal.TestMethodWorker.invokeTestMethods(TestMethodWorker.java:125)
	at org.testng.internal.TestMethodWorker.run(TestMethodWorker.java:108)
	at org.testng.TestRunner.privateRun(TestRunner.java:774)
	at org.testng.TestRunner.run(TestRunner.java:624)
	at org.testng.SuiteRunner.runTest(SuiteRunner.java:359)
	at org.testng.SuiteRunner.runSequentially(SuiteRunner.java:354)
	at org.testng.SuiteRunner.privateRun(SuiteRunner.java:312)
	at org.testng.SuiteRunner.run(SuiteRunner.java:261)
	at org.testng.SuiteRunnerWorker.runSuite(SuiteRunnerWorker.java:52)
	at org.testng.SuiteRunnerWorker.run(SuiteRunnerWorker.java:86)
	at org.testng.TestNG.runSuitesSequentially(TestNG.java:1215)
	at org.testng.TestNG.runSuitesSequentially(TestNG.java:1211)
	at org.testng.TestNG.runSuitesLocally(TestNG.java:1140)
	at org.testng.TestNG.run(TestNG.java:1048)
	at org.testng.TestNG.privateMain(TestNG.java:1355)
	at org.testng.TestNG.main(TestNG.java:1324)
]]>
            </full-stacktrace>
          </exception> <!-- java.lang.AssertionError -->
          <reporter-output>
          </reporter-output>
        </test-method> <!-- testB1_3 -->
      </class> <!-- testSuiteB.TestB1 -->
    </test> <!-- Test B1 -->
    <test name="Test B2" duration-ms="1" started-at="2017-01-20T07:12:41Z" finished-at="2017-01-20T07:12:41Z">
      <class name="testSuiteB.TestB2">
        <test-method status="FAIL" signature="testB2_2()[pri:0, instance:testSuiteB.TestB2@3c5a99da]" name="testB2_2" duration-ms="1" started-at="2017-01-20T00:12:41Z" finished-at="2017-01-20T00:12:41Z">
          <exception class="java.lang.AssertionError">
            <message>
              <![CDATA[failed test case ]]>
            </message>
            <full-stacktrace>
              <![CDATA[java.lang.AssertionError: failed test case 
	at org.testng.Assert.fail(Assert.java:94)
	at testSuiteB.TestB2.testB2_2(TestB2.java:16)
	at sun.reflect.NativeMethodAccessorImpl.invoke0(Native Method)
	at sun.reflect.NativeMethodAccessorImpl.invoke(NativeMethodAccessorImpl.java:62)
	at sun.reflect.DelegatingMethodAccessorImpl.invoke(DelegatingMethodAccessorImpl.java:43)
	at java.lang.reflect.Method.invoke(Method.java:498)
	at org.testng.internal.MethodInvocationHelper.invokeMethod(MethodInvocationHelper.java:85)
	at org.testng.internal.Invoker.invokeMethod(Invoker.java:639)
	at org.testng.internal.Invoker.invokeTestMethod(Invoker.java:816)
	at org.testng.internal.Invoker.invokeTestMethods(Invoker.java:1124)
	at org.testng.internal.TestMethodWorker.invokeTestMethods(TestMethodWorker.java:125)
	at org.testng.internal.TestMethodWorker.run(TestMethodWorker.java:108)
	at org.testng.TestRunner.privateRun(TestRunner.java:774)
	at org.testng.TestRunner.run(TestRunner.java:624)
	at org.testng.SuiteRunner.runTest(SuiteRunner.java:359)
	at org.testng.SuiteRunner.runSequentially(SuiteRunner.java:354)
	at org.testng.SuiteRunner.privateRun(SuiteRunner.java:312)
	at org.testng.SuiteRunner.run(SuiteRunner.java:261)
	at org.testng.SuiteRunnerWorker.runSuite(SuiteRunnerWorker.java:52)
	at org.testng.SuiteRunnerWorker.run(SuiteRunnerWorker.java:86)
	at org.testng.TestNG.runSuitesSequentially(TestNG.java:1215)
	at org.testng.TestNG.runSuitesSequentially(TestNG.java:1211)
	at org.testng.TestNG.runSuitesLocally(TestNG.java:1140)
	at org.testng.TestNG.run(TestNG.java:1048)
	at org.testng.TestNG.privateMain(TestNG.java:1355)
	at org.testng.TestNG.main(TestNG.java:1324)
]]>
            </full-stacktrace>
          </exception> <!-- java.lang.AssertionError -->
          <reporter-output>
          </reporter-output>
        </test-method> <!-- testB2_2 -->
        <test-method status="PASS" signature="testB2_1()[pri:0, instance:testSuiteB.TestB2@3c5a99da]" name="testB2_1" duration-ms="0" started-at="2017-01-20T00:12:41Z" finished-at="2017-01-20T00:12:41Z">
          <reporter-output>
          </reporter-output>
        </test-method> <!-- testB2_1 -->
        <test-method status="PASS" signature="testB2_3()[pri:0, instance:testSuiteB.TestB2@3c5a99da]" name="testB2_3" duration-ms="0" started-at="2017-01-20T00:12:41Z" finished-at="2017-01-20T00:12:41Z">
          <reporter-output>
          </reporter-output>
        </test-method> <!-- testB2_3 -->
      </class> <!-- testSuiteB.TestB2 -->
    </test> <!-- Test B2 -->
  </suite> <!-- Suite B -->
  <suite name="Suite A" duration-ms="662" started-at="2017-01-20T07:12:41Z" finished-at="2017-01-20T07:12:41Z">
    <groups>
    </groups>
    <test name="Test A1" duration-ms="24" started-at="2017-01-20T07:12:41Z" finished-at="2017-01-20T07:12:41Z">
      <class name="testSuiteA.TestA1">
        <test-method status="SKIP" signature="testA1_1()[pri:0, instance:testSuiteA.TestA1@61a52fbd]" name="testA1_1" duration-ms="9" started-at="2017-01-20T00:12:41Z" finished-at="2017-01-20T00:12:41Z">
          <exception class="org.testng.SkipException">
            <message>
              <![CDATA[Skipping the test]]>
            </message>
            <full-stacktrace>
              <![CDATA[org.testng.SkipException: Skipping the test
	at testSuiteA.TestA1.testA1_1(TestA1.java:12)
	at sun.reflect.NativeMethodAccessorImpl.invoke0(Native Method)
	at sun.reflect.NativeMethodAccessorImpl.invoke(NativeMethodAccessorImpl.java:62)
	at sun.reflect.DelegatingMethodAccessorImpl.invoke(DelegatingMethodAccessorImpl.java:43)
	at java.lang.reflect.Method.invoke(Method.java:498)
	at org.testng.internal.MethodInvocationHelper.invokeMethod(MethodInvocationHelper.java:85)
	at org.testng.internal.Invoker.invokeMethod(Invoker.java:639)
	at org.testng.internal.Invoker.invokeTestMethod(Invoker.java:816)
	at org.testng.internal.Invoker.invokeTestMethods(Invoker.java:1124)
	at org.testng.internal.TestMethodWorker.invokeTestMethods(TestMethodWorker.java:125)
	at org.testng.internal.TestMethodWorker.run(TestMethodWorker.java:108)
	at org.testng.TestRunner.privateRun(TestRunner.java:774)
	at org.testng.TestRunner.run(TestRunner.java:624)
	at org.testng.SuiteRunner.runTest(SuiteRunner.java:359)
	at org.testng.SuiteRunner.runSequentially(SuiteRunner.java:354)
	at org.testng.SuiteRunner.privateRun(SuiteRunner.java:312)
	at org.testng.SuiteRunner.run(SuiteRunner.java:261)
	at org.testng.SuiteRunnerWorker.runSuite(SuiteRunnerWorker.java:52)
	at org.testng.SuiteRunnerWorker.run(SuiteRunnerWorker.java:86)
	at org.testng.TestNG.runSuitesSequentially(TestNG.java:1215)
	at org.testng.TestNG.runSuitesSequentially(TestNG.java:1211)
	at org.testng.TestNG.runSuitesLocally(TestNG.java:1140)
	at org.testng.TestNG.run(TestNG.java:1048)
	at org.testng.TestNG.privateMain(TestNG.java:1355)
	at org.testng.TestNG.main(TestNG.java:1324)
]]>
            </full-stacktrace>
          </exception> <!-- org.testng.SkipException -->
          <reporter-output>
          </reporter-output>
        </test-method> <!-- testA1_1 -->
        <test-method status="PASS" signature="testA1_2()[pri:0, instance:testSuiteA.TestA1@61a52fbd]" name="testA1_2" duration-ms="0" started-at="2017-01-20T00:12:41Z" finished-at="2017-01-20T00:12:41Z">
          <reporter-output>
          </reporter-output>
        </test-method> <!-- testA1_2 -->
        <test-method status="FAIL" signature="testA1_3()[pri:0, instance:testSuiteA.TestA1@61a52fbd]" name="testA1_3" duration-ms="2" started-at="2017-01-20T00:12:41Z" finished-at="2017-01-20T00:12:41Z">
          <exception class="java.lang.AssertionError">
            <message>
              <![CDATA[failed test case ]]>
            </message>
            <full-stacktrace>
              <![CDATA[java.lang.AssertionError: failed test case 
	at org.testng.Assert.fail(Assert.java:94)
	at testSuiteA.TestA1.testA1_3(TestA1.java:23)
	at sun.reflect.NativeMethodAccessorImpl.invoke0(Native Method)
	at sun.reflect.NativeMethodAccessorImpl.invoke(NativeMethodAccessorImpl.java:62)
	at sun.reflect.DelegatingMethodAccessorImpl.invoke(DelegatingMethodAccessorImpl.java:43)
	at java.lang.reflect.Method.invoke(Method.java:498)
	at org.testng.internal.MethodInvocationHelper.invokeMethod(MethodInvocationHelper.java:85)
	at org.testng.internal.Invoker.invokeMethod(Invoker.java:639)
	at org.testng.internal.Invoker.invokeTestMethod(Invoker.java:816)
	at org.testng.internal.Invoker.invokeTestMethods(Invoker.java:1124)
	at org.testng.internal.TestMethodWorker.invokeTestMethods(TestMethodWorker.java:125)
	at org.testng.internal.TestMethodWorker.run(TestMethodWorker.java:108)
	at org.testng.TestRunner.privateRun(TestRunner.java:774)
	at org.testng.TestRunner.run(TestRunner.java:624)
	at org.testng.SuiteRunner.runTest(SuiteRunner.java:359)
	at org.testng.SuiteRunner.runSequentially(SuiteRunner.java:354)
	at org.testng.SuiteRunner.privateRun(SuiteRunner.java:312)
	at org.testng.SuiteRunner.run(SuiteRunner.java:261)
	at org.testng.SuiteRunnerWorker.runSuite(SuiteRunnerWorker.java:52)
	at org.testng.SuiteRunnerWorker.run(SuiteRunnerWorker.java:86)
	at org.testng.TestNG.runSuitesSequentially(TestNG.java:1215)
	at org.testng.TestNG.runSuitesSequentially(TestNG.java:1211)
	at org.testng.TestNG.runSuitesLocally(TestNG.java:1140)
	at org.testng.TestNG.run(TestNG.java:1048)
	at org.testng.TestNG.privateMain(TestNG.java:1355)
	at org.testng.TestNG.main(TestNG.java:1324)
]]>
            </full-stacktrace>
          </exception> <!-- java.lang.AssertionError -->
          <reporter-output>
          </reporter-output>
        </test-method> <!-- testA1_3 -->
      </class> <!-- testSuiteA.TestA1 -->
    </test> <!-- Test A1 -->
    <test name="Test A2" duration-ms="5" started-at="2017-01-20T07:12:41Z" finished-at="2017-01-20T07:12:41Z">
      <class name="testSuiteA.TestA2">
        <test-method status="PASS" signature="testA2_3()[pri:0, instance:testSuiteA.TestA2@2aaf7cc2]" name="testA2_3" duration-ms="0" started-at="2017-01-20T00:12:41Z" finished-at="2017-01-20T00:12:41Z">
          <reporter-output>
          </reporter-output>
        </test-method> <!-- testA2_3 -->
        <test-method status="PASS" signature="testA2_1()[pri:0, instance:testSuiteA.TestA2@2aaf7cc2]" name="testA2_1" duration-ms="0" started-at="2017-01-20T00:12:41Z" finished-at="2017-01-20T00:12:41Z">
          <reporter-output>
          </reporter-output>
        </test-method> <!-- testA2_1 -->
        <test-method status="FAIL" signature="testA2_2()[pri:0, instance:testSuiteA.TestA2@2aaf7cc2]" name="testA2_2" duration-ms="0" started-at="2017-01-20T00:12:41Z" finished-at="2017-01-20T00:12:41Z">
          <exception class="java.lang.AssertionError">
            <message>
              <![CDATA[failed test case ]]>
            </message>
            <full-stacktrace>
              <![CDATA[java.lang.AssertionError: failed test case 
	at org.testng.Assert.fail(Assert.java:94)
	at testSuiteA.TestA2.testA2_2(TestA2.java:16)
	at sun.reflect.NativeMethodAccessorImpl.invoke0(Native Method)
	at sun.reflect.NativeMethodAccessorImpl.invoke(NativeMethodAccessorImpl.java:62)
	at sun.reflect.DelegatingMethodAccessorImpl.invoke(DelegatingMethodAccessorImpl.java:43)
	at java.lang.reflect.Method.invoke(Method.java:498)
	at org.testng.internal.MethodInvocationHelper.invokeMethod(MethodInvocationHelper.java:85)
	at org.testng.internal.Invoker.invokeMethod(Invoker.java:639)
	at org.testng.internal.Invoker.invokeTestMethod(Invoker.java:816)
	at org.testng.internal.Invoker.invokeTestMethods(Invoker.java:1124)
	at org.testng.internal.TestMethodWorker.invokeTestMethods(TestMethodWorker.java:125)
	at org.testng.internal.TestMethodWorker.run(TestMethodWorker.java:108)
	at org.testng.TestRunner.privateRun(TestRunner.java:774)
	at org.testng.TestRunner.run(TestRunner.java:624)
	at org.testng.SuiteRunner.runTest(SuiteRunner.java:359)
	at org.testng.SuiteRunner.runSequentially(SuiteRunner.java:354)
	at org.testng.SuiteRunner.privateRun(SuiteRunner.java:312)
	at org.testng.SuiteRunner.run(SuiteRunner.java:261)
	at org.testng.SuiteRunnerWorker.runSuite(SuiteRunnerWorker.java:52)
	at org.testng.SuiteRunnerWorker.run(SuiteRunnerWorker.java:86)
	at org.testng.TestNG.runSuitesSequentially(TestNG.java:1215)
	at org.testng.TestNG.runSuitesSequentially(TestNG.java:1211)
	at org.testng.TestNG.runSuitesLocally(TestNG.java:1140)
	at org.testng.TestNG.run(TestNG.java:1048)
	at org.testng.TestNG.privateMain(TestNG.java:1355)
	at org.testng.TestNG.main(TestNG.java:1324)
]]>
            </full-stacktrace>
          </exception> <!-- java.lang.AssertionError -->
          <reporter-output>
          </reporter-output>
        </test-method> <!-- testA2_2 -->
      </class> <!-- testSuiteA.TestA2 -->
    </test> <!-- Test A2 -->
  </suite> <!-- Suite A -->
  <suite name="My suite" duration-ms="0" started-at="2017-01-20T07:12:41Z" finished-at="2017-01-20T07:12:41Z">
    <groups>
    </groups>
  </suite> <!-- My suite -->
</testng-results>
